[2023-12-20 19:12:34,330] {taskinstance.py:1043} INFO - Dependencies all met for <TaskInstance: s3_to_postgres_dag.push_to_postgres manual__2023-12-20T19:12:29.765529+00:00 [queued]>
[2023-12-20 19:12:34,342] {taskinstance.py:1043} INFO - Dependencies all met for <TaskInstance: s3_to_postgres_dag.push_to_postgres manual__2023-12-20T19:12:29.765529+00:00 [queued]>
[2023-12-20 19:12:34,343] {taskinstance.py:1249} INFO - 
--------------------------------------------------------------------------------
[2023-12-20 19:12:34,344] {taskinstance.py:1250} INFO - Starting attempt 1 of 1
[2023-12-20 19:12:34,344] {taskinstance.py:1251} INFO - 
--------------------------------------------------------------------------------
[2023-12-20 19:12:34,357] {taskinstance.py:1270} INFO - Executing <Task(PythonOperator): push_to_postgres> on 2023-12-20 19:12:29.765529+00:00
[2023-12-20 19:12:34,362] {standard_task_runner.py:52} INFO - Started process 6138 to run task
[2023-12-20 19:12:34,365] {standard_task_runner.py:79} INFO - Running: ['***', 'tasks', 'run', 's3_to_postgres_dag', 'push_to_postgres', 'manual__2023-12-20T19:12:29.765529+00:00', '--job-id', '20', '--raw', '--subdir', 'DAGS_FOLDER/first_dag.py', '--cfg-path', '/tmp/tmphpdwhlfc', '--error-file', '/tmp/tmpz5z1wgly']
[2023-12-20 19:12:34,366] {standard_task_runner.py:80} INFO - Job 20: Subtask push_to_postgres
[2023-12-20 19:12:34,415] {logging_mixin.py:109} INFO - Running <TaskInstance: s3_to_postgres_dag.push_to_postgres manual__2023-12-20T19:12:29.765529+00:00 [running]> on host eddfb0464777
[2023-12-20 19:12:34,454] {taskinstance.py:1448} INFO - Exporting the following env vars:
AIRFLOW_CTX_DAG_OWNER=***
AIRFLOW_CTX_DAG_ID=s3_to_postgres_dag
AIRFLOW_CTX_TASK_ID=push_to_postgres
AIRFLOW_CTX_EXECUTION_DATE=2023-12-20T19:12:29.765529+00:00
AIRFLOW_CTX_DAG_RUN_ID=manual__2023-12-20T19:12:29.765529+00:00
[2023-12-20 19:12:34,821] {logging_mixin.py:109} INFO - Index(['STORE_ID', 'STORE_LOCATION', 'PRODUCT_CATEGORY', 'PRODUCT_ID', 'MRP',
       'CP', 'DISCOUNT', 'SP', 'Date'],
      dtype='object')
[2023-12-20 19:12:34,997] {taskinstance.py:1774} ERROR - Task failed with exception
Traceback (most recent call last):
  File "/home/airflow/.local/lib/python3.6/site-packages/airflow/operators/python.py", line 174, in execute
    return_value = self.execute_callable()
  File "/home/airflow/.local/lib/python3.6/site-packages/airflow/operators/python.py", line 188, in execute_callable
    return self.python_callable(*self.op_args, **self.op_kwargs)
  File "/opt/airflow/dags/first_dag.py", line 53, in push_to_postgres
    port=5432
  File "/home/airflow/.local/lib/python3.6/site-packages/psycopg2/__init__.py", line 122, in connect
    conn = _connect(dsn, connection_factory=connection_factory, **kwasync)
psycopg2.OperationalError: connection to server at "transactionsdb.cxym4ik0szfd.eu-west-2.rds.amazonaws.com" (18.168.185.9), port 5432 failed: FATAL:  database "transactionsdb" does not exist

[2023-12-20 19:12:35,049] {taskinstance.py:1288} INFO - Marking task as FAILED. dag_id=s3_to_postgres_dag, task_id=push_to_postgres, execution_date=20231220T191229, start_date=20231220T191234, end_date=20231220T191235
[2023-12-20 19:12:35,063] {standard_task_runner.py:98} ERROR - Failed to execute job 20 for task push_to_postgres (connection to server at "transactionsdb.cxym4ik0szfd.eu-west-2.rds.amazonaws.com" (18.168.185.9), port 5432 failed: FATAL:  database "transactionsdb" does not exist
; 6138)
[2023-12-20 19:12:35,105] {local_task_job.py:154} INFO - Task exited with return code 1
[2023-12-20 19:12:35,136] {local_task_job.py:264} INFO - 0 downstream tasks scheduled from follow-on schedule check
